<?xml version="1.0" encoding="utf-8"?>
<!-- =================================================================================== -->
<!-- |    This document was autogenerated by xacro from /mnt/d/ROS/ROSManipulator/simulation_ws/src/manipulator_description/urdf/manipulator.xacro | -->
<!-- |    EDITING THIS FILE BY HAND IS NOT RECOMMENDED                                 | -->
<!-- =================================================================================== -->
<robot name="manipulator" xmlns:xacro="http://www.ros.org/wiki/xacro">
  <link name="base_link">
    <visual>
      <origin rpy="0 0 0" xyz="0 0 0.1"/>
      <geometry>
        <box size="1 1 0.2"/>
      </geometry>
    </visual>
  </link>
  <joint name="base_link__link_1" type="revolute">
    <axis xyz="0 0 1"/>
    <limit effort="1000.0" lower="-3.14" upper="3.14" velocity="0.5"/>
    <origin rpy="0 0 0" xyz="0 0 0.2"/>
    <parent link="base_link"/>
    <child link="link1"/>
  </joint>
  <link name="link1">
    <visual>
      <origin rpy="0 0 0" xyz="0 0 0.1"/>
      <geometry>
        <cylinder length="0.2" radius="0.35"/>
      </geometry>
    </visual>
  </link>
  <joint name="link_1__link_2" type="revolute">
    <axis xyz="0 1 0"/>
    <limit effort="1000.0" lower="-3.14" upper="3.14" velocity="0.5"/>
    <origin rpy="0 0 0" xyz="0 0 0.2"/>
    <parent link="link1"/>
    <child link="link2"/>
  </joint>
  <link name="link2">
    <visual>
      <origin rpy="0 0 0" xyz="0 0 0.5"/>
      <geometry>
        <cylinder length="1" radius="0.15"/>
      </geometry>
    </visual>
  </link>
  <joint name="link_2__link_3" type="revolute">
    <axis xyz="0 1 0"/>
    <limit effort="1000.0" lower="-3.14" upper="3.14" velocity="0.5"/>
    <origin rpy="0 0 0" xyz="0 0 1"/>
    <parent link="link2"/>
    <child link="link3"/>
  </joint>
  <link name="link3">
    <visual>
      <origin rpy="0 0 0" xyz="0 0 0.5"/>
      <geometry>
        <cylinder length="1" radius="0.15"/>
      </geometry>
    </visual>
  </link>
</robot>
